Ignoring exception in command None:
discord.ext.commands.errors.CommandNotFound: Command "fjsadklfjsadjfasdlf" is not found
Ignoring exception in command None:
discord.ext.commands.errors.CommandNotFound: Command "soure" is not found
Termino is ready to go.
-----------------------------------
Ignoring exception in command slap:
Traceback (most recent call last):
  File "/usr/local/lib/python3.7/dist-packages/discord/ext/commands/core.py", line 451, in _actual_conversion
    ret = await instance.convert(ctx, argument)
  File "/root/Termino/scripts/converters.py", line 6, in convert
    random_member = random.choice(ctx.guild.members)
AttributeError: 'NoneType' object has no attribute 'members'

The above exception was the direct cause of the following exception:

Traceback (most recent call last):
  File "/usr/local/lib/python3.7/dist-packages/discord/ext/commands/bot.py", line 902, in invoke
    await ctx.command.invoke(ctx)
  File "/usr/local/lib/python3.7/dist-packages/discord/ext/commands/core.py", line 856, in invoke
    await self.prepare(ctx)
  File "/usr/local/lib/python3.7/dist-packages/discord/ext/commands/core.py", line 790, in prepare
    await self._parse_arguments(ctx)
  File "/usr/local/lib/python3.7/dist-packages/discord/ext/commands/core.py", line 697, in _parse_arguments
    transformed = await self.transform(ctx, param)
  File "/usr/local/lib/python3.7/dist-packages/discord/ext/commands/core.py", line 552, in transform
    return await self.do_conversion(ctx, converter, argument, param)
  File "/usr/local/lib/python3.7/dist-packages/discord/ext/commands/core.py", line 505, in do_conversion
    return await self._actual_conversion(ctx, converter, argument, param)
  File "/usr/local/lib/python3.7/dist-packages/discord/ext/commands/core.py", line 464, in _actual_conversion
    raise ConversionError(converter, exc) from exc
discord.ext.commands.errors.ConversionError: (<class 'converters.SlapSomeone'>, AttributeError("'NoneType' object has no attribute 'members'"))
Termino is ready to go.
-----------------------------------
Termino is ready to go.
-----------------------------------
Termino is ready to go.
-----------------------------------
Ignoring exception in command None:
discord.ext.commands.errors.CommandNotFound: Command "8ball" is not found
Ignoring exception in command None:
discord.ext.commands.errors.CommandNotFound: Command "8ball" is not found
Termino is ready to go.
-----------------------------------
  File "bot.py", line 13
    print('-----------------------------------'))
                                                ^
SyntaxError: invalid syntax
Termino is ready to go.
-----------------------------------
Termino is ready to go.
-----------------------------------
Termino is ready to go.
-----------------------------------
Ignoring exception in command None:
discord.ext.commands.errors.CommandNotFound: Command "sourxe" is not found
Ignoring exception in command None:
discord.ext.commands.errors.CommandNotFound: Command "say" is not found
Ignoring exception in command None:
discord.ext.commands.errors.CommandNotFound: Command "hepl" is not found
Termino is ready to go.
-----------------------------------
Termino is ready to go.
-----------------------------------
Ignoring exception in command None:
discord.ext.commands.errors.CommandNotFound: Command "version" is not found
Termino is ready to go.
-----------------------------------
Traceback (most recent call last):
  File "bot.py", line 2, in <module>
    import discord
ModuleNotFoundError: No module named 'discord'
Termino is ready to go.
-----------------------------------
Ignoring exception in command add:
Traceback (most recent call last):
  File "/home/pi/Termino/termino/lib/python3.7/site-packages/discord/ext/commands/core.py", line 467, in _actual_conversion
    return converter(argument)
ValueError: could not convert string to float: 'w'

The above exception was the direct cause of the following exception:

Traceback (most recent call last):
  File "/home/pi/Termino/termino/lib/python3.7/site-packages/discord/ext/commands/bot.py", line 939, in invoke
    await ctx.command.invoke(ctx)
  File "/home/pi/Termino/termino/lib/python3.7/site-packages/discord/ext/commands/core.py", line 855, in invoke
    await self.prepare(ctx)
  File "/home/pi/Termino/termino/lib/python3.7/site-packages/discord/ext/commands/core.py", line 789, in prepare
    await self._parse_arguments(ctx)
  File "/home/pi/Termino/termino/lib/python3.7/site-packages/discord/ext/commands/core.py", line 697, in _parse_arguments
    transformed = await self.transform(ctx, param)
  File "/home/pi/Termino/termino/lib/python3.7/site-packages/discord/ext/commands/core.py", line 552, in transform
    return await self.do_conversion(ctx, converter, argument, param)
  File "/home/pi/Termino/termino/lib/python3.7/site-packages/discord/ext/commands/core.py", line 505, in do_conversion
    return await self._actual_conversion(ctx, converter, argument, param)
  File "/home/pi/Termino/termino/lib/python3.7/site-packages/discord/ext/commands/core.py", line 476, in _actual_conversion
    raise BadArgument('Converting to "{}" failed for parameter "{}".'.format(name, param.name)) from exc
discord.ext.commands.errors.BadArgument: Converting to "float" failed for parameter "addend2".
Termino is ready to go.
-----------------------------------
Termino is ready to go.
-----------------------------------
Termino is ready to go.
-----------------------------------
Termino is ready to go.
-----------------------------------
Termino is ready to go.
-----------------------------------
Fatal read error on socket transport
protocol: <asyncio.sslproto.SSLProtocol object at 0xb3d854f0>
transport: <_SelectorSocketTransport fd=7 read=polling write=<idle, bufsize=0>>
Traceback (most recent call last):
  File "/usr/lib/python3.7/asyncio/selector_events.py", line 801, in _read_ready__data_received
    data = self._sock.recv(self.max_size)
OSError: [Errno 101] Network is unreachable
Termino is ready to go.
-----------------------------------
Traceback (most recent call last):
  File "bot.py", line 2, in <module>
    import discord
ModuleNotFoundError: No module named 'discord'
Termino is ready to go.
-----------------------------------
Ignoring exception in command add:
Traceback (most recent call last):
  File "/home/pi/Termino/termino/lib/python3.7/site-packages/discord/ext/commands/core.py", line 467, in _actual_conversion
    return converter(argument)
ValueError: could not convert string to float: '1.22.1'

The above exception was the direct cause of the following exception:

Traceback (most recent call last):
  File "/home/pi/Termino/termino/lib/python3.7/site-packages/discord/ext/commands/bot.py", line 939, in invoke
    await ctx.command.invoke(ctx)
  File "/home/pi/Termino/termino/lib/python3.7/site-packages/discord/ext/commands/core.py", line 855, in invoke
    await self.prepare(ctx)
  File "/home/pi/Termino/termino/lib/python3.7/site-packages/discord/ext/commands/core.py", line 789, in prepare
    await self._parse_arguments(ctx)
  File "/home/pi/Termino/termino/lib/python3.7/site-packages/discord/ext/commands/core.py", line 697, in _parse_arguments
    transformed = await self.transform(ctx, param)
  File "/home/pi/Termino/termino/lib/python3.7/site-packages/discord/ext/commands/core.py", line 552, in transform
    return await self.do_conversion(ctx, converter, argument, param)
  File "/home/pi/Termino/termino/lib/python3.7/site-packages/discord/ext/commands/core.py", line 505, in do_conversion
    return await self._actual_conversion(ctx, converter, argument, param)
  File "/home/pi/Termino/termino/lib/python3.7/site-packages/discord/ext/commands/core.py", line 476, in _actual_conversion
    raise BadArgument('Converting to "{}" failed for parameter "{}".'.format(name, param.name)) from exc
discord.ext.commands.errors.BadArgument: Converting to "float" failed for parameter "addend1".
Termino is ready to go.
-----------------------------------
Termino is ready to go.
-----------------------------------
Traceback (most recent call last):
  File "bot.py", line 2, in <module>
    import discord
ModuleNotFoundError: No module named 'discord'
  File "bot.py", line 64
    embd = discord.Embed(description = f"ctx.author.mention} slapped {member.mention} because of {reason}.")
                                      ^
SyntaxError: f-string: single '}' is not allowed
Ignoring exception in command slap:
Traceback (most recent call last):
  File "/home/pi/Termino/termino/lib/python3.7/site-packages/discord/ext/commands/core.py", line 85, in wrapped
    ret = await coro(*args, **kwargs)
  File "bot.py", line 65, in slap
    embed.set_image = "https://tenor.com/davie504-slap-slappers-davie-you-tuber-gif-16545714"
NameError: name 'embed' is not defined

The above exception was the direct cause of the following exception:

Traceback (most recent call last):
  File "/home/pi/Termino/termino/lib/python3.7/site-packages/discord/ext/commands/bot.py", line 939, in invoke
    await ctx.command.invoke(ctx)
  File "/home/pi/Termino/termino/lib/python3.7/site-packages/discord/ext/commands/core.py", line 863, in invoke
    await injected(*ctx.args, **ctx.kwargs)
  File "/home/pi/Termino/termino/lib/python3.7/site-packages/discord/ext/commands/core.py", line 94, in wrapped
    raise CommandInvokeError(exc) from exc
discord.ext.commands.errors.CommandInvokeError: Command raised an exception: NameError: name 'embed' is not defined
Termino is ready to go.
-----------------------------------
Termino is ready to go.
-----------------------------------
Traceback (most recent call last):
  File "bot.py", line 2, in <module>
    import discord
ModuleNotFoundError: No module named 'discord'
Termino is ready to go.
-----------------------------------
Termino is ready to go.
-----------------------------------
Ignoring exception in command slap:
Traceback (most recent call last):
  File "/home/pi/Termino/termino/lib/python3.7/site-packages/discord/ext/commands/bot.py", line 939, in invoke
    await ctx.command.invoke(ctx)
  File "/home/pi/Termino/termino/lib/python3.7/site-packages/discord/ext/commands/core.py", line 855, in invoke
    await self.prepare(ctx)
  File "/home/pi/Termino/termino/lib/python3.7/site-packages/discord/ext/commands/core.py", line 789, in prepare
    await self._parse_arguments(ctx)
  File "/home/pi/Termino/termino/lib/python3.7/site-packages/discord/ext/commands/core.py", line 697, in _parse_arguments
    transformed = await self.transform(ctx, param)
  File "/home/pi/Termino/termino/lib/python3.7/site-packages/discord/ext/commands/core.py", line 552, in transform
    return await self.do_conversion(ctx, converter, argument, param)
  File "/home/pi/Termino/termino/lib/python3.7/site-packages/discord/ext/commands/core.py", line 505, in do_conversion
    return await self._actual_conversion(ctx, converter, argument, param)
  File "/home/pi/Termino/termino/lib/python3.7/site-packages/discord/ext/commands/core.py", line 451, in _actual_conversion
    ret = await instance.convert(ctx, argument)
  File "/home/pi/Termino/termino/lib/python3.7/site-packages/discord/ext/commands/converter.py", line 195, in convert
    raise MemberNotFound(argument)
discord.ext.commands.errors.MemberNotFound: Member "<@&821508396150292523>" not found.
Termino is ready to go.
-----------------------------------
