Ignoring exception in command None:
discord.ext.commands.errors.CommandNotFound: Command "fjsadklfjsadjfasdlf" is not found
Ignoring exception in command None:
discord.ext.commands.errors.CommandNotFound: Command "soure" is not found
Termino is ready to go.
-----------------------------------
Ignoring exception in command slap:
Traceback (most recent call last):
  File "/usr/local/lib/python3.7/dist-packages/discord/ext/commands/core.py", line 451, in _actual_conversion
    ret = await instance.convert(ctx, argument)
  File "/root/Termino/scripts/converters.py", line 6, in convert
    random_member = random.choice(ctx.guild.members)
AttributeError: 'NoneType' object has no attribute 'members'

The above exception was the direct cause of the following exception:

Traceback (most recent call last):
  File "/usr/local/lib/python3.7/dist-packages/discord/ext/commands/bot.py", line 902, in invoke
    await ctx.command.invoke(ctx)
  File "/usr/local/lib/python3.7/dist-packages/discord/ext/commands/core.py", line 856, in invoke
    await self.prepare(ctx)
  File "/usr/local/lib/python3.7/dist-packages/discord/ext/commands/core.py", line 790, in prepare
    await self._parse_arguments(ctx)
  File "/usr/local/lib/python3.7/dist-packages/discord/ext/commands/core.py", line 697, in _parse_arguments
    transformed = await self.transform(ctx, param)
  File "/usr/local/lib/python3.7/dist-packages/discord/ext/commands/core.py", line 552, in transform
    return await self.do_conversion(ctx, converter, argument, param)
  File "/usr/local/lib/python3.7/dist-packages/discord/ext/commands/core.py", line 505, in do_conversion
    return await self._actual_conversion(ctx, converter, argument, param)
  File "/usr/local/lib/python3.7/dist-packages/discord/ext/commands/core.py", line 464, in _actual_conversion
    raise ConversionError(converter, exc) from exc
discord.ext.commands.errors.ConversionError: (<class 'converters.SlapSomeone'>, AttributeError("'NoneType' object has no attribute 'members'"))
Termino is ready to go.
-----------------------------------
Termino is ready to go.
-----------------------------------
Termino is ready to go.
-----------------------------------
Ignoring exception in command None:
discord.ext.commands.errors.CommandNotFound: Command "8ball" is not found
Ignoring exception in command None:
discord.ext.commands.errors.CommandNotFound: Command "8ball" is not found
Termino is ready to go.
-----------------------------------
  File "bot.py", line 13
    print('-----------------------------------'))
                                                ^
SyntaxError: invalid syntax
Termino is ready to go.
-----------------------------------
Termino is ready to go.
-----------------------------------
Termino is ready to go.
-----------------------------------
Ignoring exception in command None:
discord.ext.commands.errors.CommandNotFound: Command "sourxe" is not found
Ignoring exception in command None:
discord.ext.commands.errors.CommandNotFound: Command "say" is not found
Ignoring exception in command None:
discord.ext.commands.errors.CommandNotFound: Command "hepl" is not found
Termino is ready to go.
-----------------------------------
Termino is ready to go.
-----------------------------------
Ignoring exception in command None:
discord.ext.commands.errors.CommandNotFound: Command "version" is not found
Termino is ready to go.
-----------------------------------
Traceback (most recent call last):
  File "bot.py", line 2, in <module>
    import discord
ModuleNotFoundError: No module named 'discord'
Termino is ready to go.
-----------------------------------
Ignoring exception in command add:
Traceback (most recent call last):
  File "/home/pi/Termino/termino/lib/python3.7/site-packages/discord/ext/commands/core.py", line 467, in _actual_conversion
    return converter(argument)
ValueError: could not convert string to float: 'w'

The above exception was the direct cause of the following exception:

Traceback (most recent call last):
  File "/home/pi/Termino/termino/lib/python3.7/site-packages/discord/ext/commands/bot.py", line 939, in invoke
    await ctx.command.invoke(ctx)
  File "/home/pi/Termino/termino/lib/python3.7/site-packages/discord/ext/commands/core.py", line 855, in invoke
    await self.prepare(ctx)
  File "/home/pi/Termino/termino/lib/python3.7/site-packages/discord/ext/commands/core.py", line 789, in prepare
    await self._parse_arguments(ctx)
  File "/home/pi/Termino/termino/lib/python3.7/site-packages/discord/ext/commands/core.py", line 697, in _parse_arguments
    transformed = await self.transform(ctx, param)
  File "/home/pi/Termino/termino/lib/python3.7/site-packages/discord/ext/commands/core.py", line 552, in transform
    return await self.do_conversion(ctx, converter, argument, param)
  File "/home/pi/Termino/termino/lib/python3.7/site-packages/discord/ext/commands/core.py", line 505, in do_conversion
    return await self._actual_conversion(ctx, converter, argument, param)
  File "/home/pi/Termino/termino/lib/python3.7/site-packages/discord/ext/commands/core.py", line 476, in _actual_conversion
    raise BadArgument('Converting to "{}" failed for parameter "{}".'.format(name, param.name)) from exc
discord.ext.commands.errors.BadArgument: Converting to "float" failed for parameter "addend2".
Termino is ready to go.
-----------------------------------
Termino is ready to go.
-----------------------------------
Termino is ready to go.
-----------------------------------
Termino is ready to go.
-----------------------------------
Termino is ready to go.
-----------------------------------
Fatal read error on socket transport
protocol: <asyncio.sslproto.SSLProtocol object at 0xb3d854f0>
transport: <_SelectorSocketTransport fd=7 read=polling write=<idle, bufsize=0>>
Traceback (most recent call last):
  File "/usr/lib/python3.7/asyncio/selector_events.py", line 801, in _read_ready__data_received
    data = self._sock.recv(self.max_size)
OSError: [Errno 101] Network is unreachable
Termino is ready to go.
-----------------------------------
Traceback (most recent call last):
  File "bot.py", line 2, in <module>
    import discord
ModuleNotFoundError: No module named 'discord'
Termino is ready to go.
-----------------------------------
Ignoring exception in command add:
Traceback (most recent call last):
  File "/home/pi/Termino/termino/lib/python3.7/site-packages/discord/ext/commands/core.py", line 467, in _actual_conversion
    return converter(argument)
ValueError: could not convert string to float: '1.22.1'

The above exception was the direct cause of the following exception:

Traceback (most recent call last):
  File "/home/pi/Termino/termino/lib/python3.7/site-packages/discord/ext/commands/bot.py", line 939, in invoke
    await ctx.command.invoke(ctx)
  File "/home/pi/Termino/termino/lib/python3.7/site-packages/discord/ext/commands/core.py", line 855, in invoke
    await self.prepare(ctx)
  File "/home/pi/Termino/termino/lib/python3.7/site-packages/discord/ext/commands/core.py", line 789, in prepare
    await self._parse_arguments(ctx)
  File "/home/pi/Termino/termino/lib/python3.7/site-packages/discord/ext/commands/core.py", line 697, in _parse_arguments
    transformed = await self.transform(ctx, param)
  File "/home/pi/Termino/termino/lib/python3.7/site-packages/discord/ext/commands/core.py", line 552, in transform
    return await self.do_conversion(ctx, converter, argument, param)
  File "/home/pi/Termino/termino/lib/python3.7/site-packages/discord/ext/commands/core.py", line 505, in do_conversion
    return await self._actual_conversion(ctx, converter, argument, param)
  File "/home/pi/Termino/termino/lib/python3.7/site-packages/discord/ext/commands/core.py", line 476, in _actual_conversion
    raise BadArgument('Converting to "{}" failed for parameter "{}".'.format(name, param.name)) from exc
discord.ext.commands.errors.BadArgument: Converting to "float" failed for parameter "addend1".
Termino is ready to go.
-----------------------------------
Termino is ready to go.
-----------------------------------
Traceback (most recent call last):
  File "bot.py", line 2, in <module>
    import discord
ModuleNotFoundError: No module named 'discord'
  File "bot.py", line 64
    embd = discord.Embed(description = f"ctx.author.mention} slapped {member.mention} because of {reason}.")
                                      ^
SyntaxError: f-string: single '}' is not allowed
Ignoring exception in command slap:
Traceback (most recent call last):
  File "/home/pi/Termino/termino/lib/python3.7/site-packages/discord/ext/commands/core.py", line 85, in wrapped
    ret = await coro(*args, **kwargs)
  File "bot.py", line 65, in slap
    embed.set_image = "https://tenor.com/davie504-slap-slappers-davie-you-tuber-gif-16545714"
NameError: name 'embed' is not defined

The above exception was the direct cause of the following exception:

Traceback (most recent call last):
  File "/home/pi/Termino/termino/lib/python3.7/site-packages/discord/ext/commands/bot.py", line 939, in invoke
    await ctx.command.invoke(ctx)
  File "/home/pi/Termino/termino/lib/python3.7/site-packages/discord/ext/commands/core.py", line 863, in invoke
    await injected(*ctx.args, **ctx.kwargs)
  File "/home/pi/Termino/termino/lib/python3.7/site-packages/discord/ext/commands/core.py", line 94, in wrapped
    raise CommandInvokeError(exc) from exc
discord.ext.commands.errors.CommandInvokeError: Command raised an exception: NameError: name 'embed' is not defined
Termino is ready to go.
-----------------------------------
Termino is ready to go.
-----------------------------------
Traceback (most recent call last):
  File "bot.py", line 2, in <module>
    import discord
ModuleNotFoundError: No module named 'discord'
Termino is ready to go.
-----------------------------------
Termino is ready to go.
-----------------------------------
Ignoring exception in command slap:
Traceback (most recent call last):
  File "/home/pi/Termino/termino/lib/python3.7/site-packages/discord/ext/commands/bot.py", line 939, in invoke
    await ctx.command.invoke(ctx)
  File "/home/pi/Termino/termino/lib/python3.7/site-packages/discord/ext/commands/core.py", line 855, in invoke
    await self.prepare(ctx)
  File "/home/pi/Termino/termino/lib/python3.7/site-packages/discord/ext/commands/core.py", line 789, in prepare
    await self._parse_arguments(ctx)
  File "/home/pi/Termino/termino/lib/python3.7/site-packages/discord/ext/commands/core.py", line 697, in _parse_arguments
    transformed = await self.transform(ctx, param)
  File "/home/pi/Termino/termino/lib/python3.7/site-packages/discord/ext/commands/core.py", line 552, in transform
    return await self.do_conversion(ctx, converter, argument, param)
  File "/home/pi/Termino/termino/lib/python3.7/site-packages/discord/ext/commands/core.py", line 505, in do_conversion
    return await self._actual_conversion(ctx, converter, argument, param)
  File "/home/pi/Termino/termino/lib/python3.7/site-packages/discord/ext/commands/core.py", line 451, in _actual_conversion
    ret = await instance.convert(ctx, argument)
  File "/home/pi/Termino/termino/lib/python3.7/site-packages/discord/ext/commands/converter.py", line 195, in convert
    raise MemberNotFound(argument)
discord.ext.commands.errors.MemberNotFound: Member "<@&821508396150292523>" not found.
Termino is ready to go.
-----------------------------------
Termino is ready to go.
-----------------------------------
Ignoring exception in command randomslap:
Traceback (most recent call last):
  File "/home/pi/Termino/termino/lib/python3.7/site-packages/discord/ext/commands/core.py", line 451, in _actual_conversion
    ret = await instance.convert(ctx, argument)
  File "/home/pi/Termino/scripts/converters/advancedconverters.py", line 6, in convert
    random_member = random.choice(ctx.guild.members)
AttributeError: 'NoneType' object has no attribute 'members'

The above exception was the direct cause of the following exception:

Traceback (most recent call last):
  File "/home/pi/Termino/termino/lib/python3.7/site-packages/discord/ext/commands/bot.py", line 939, in invoke
    await ctx.command.invoke(ctx)
  File "/home/pi/Termino/termino/lib/python3.7/site-packages/discord/ext/commands/core.py", line 855, in invoke
    await self.prepare(ctx)
  File "/home/pi/Termino/termino/lib/python3.7/site-packages/discord/ext/commands/core.py", line 789, in prepare
    await self._parse_arguments(ctx)
  File "/home/pi/Termino/termino/lib/python3.7/site-packages/discord/ext/commands/core.py", line 706, in _parse_arguments
    kwargs[name] = await self.transform(ctx, param)
  File "/home/pi/Termino/termino/lib/python3.7/site-packages/discord/ext/commands/core.py", line 552, in transform
    return await self.do_conversion(ctx, converter, argument, param)
  File "/home/pi/Termino/termino/lib/python3.7/site-packages/discord/ext/commands/core.py", line 505, in do_conversion
    return await self._actual_conversion(ctx, converter, argument, param)
  File "/home/pi/Termino/termino/lib/python3.7/site-packages/discord/ext/commands/core.py", line 464, in _actual_conversion
    raise ConversionError(converter, exc) from exc
discord.ext.commands.errors.ConversionError: (<class 'converters.advancedconverters.SlapSomeone'>, AttributeError("'NoneType' object has no attribute 'members'"))
Ignoring exception in command kick:
Traceback (most recent call last):
  File "/home/pi/Termino/termino/lib/python3.7/site-packages/discord/ext/commands/core.py", line 85, in wrapped
    ret = await coro(*args, **kwargs)
  File "/home/pi/Termino/scripts/moderation/kickban.py", line 9, in kick
    await member.kick(reason = "Didn't provide a reason.")
  File "/home/pi/Termino/termino/lib/python3.7/site-packages/discord/member.py", line 555, in kick
    await self.guild.kick(self, reason=reason)
  File "/home/pi/Termino/termino/lib/python3.7/site-packages/discord/guild.py", line 1997, in kick
    await self._state.http.kick(user.id, self.id, reason=reason)
  File "/home/pi/Termino/termino/lib/python3.7/site-packages/discord/http.py", line 248, in request
    raise Forbidden(r, data)
discord.errors.Forbidden: 403 Forbidden (error code: 50013): Missing Permissions

The above exception was the direct cause of the following exception:

Traceback (most recent call last):
  File "/home/pi/Termino/termino/lib/python3.7/site-packages/discord/ext/commands/bot.py", line 939, in invoke
    await ctx.command.invoke(ctx)
  File "/home/pi/Termino/termino/lib/python3.7/site-packages/discord/ext/commands/core.py", line 863, in invoke
    await injected(*ctx.args, **ctx.kwargs)
  File "/home/pi/Termino/termino/lib/python3.7/site-packages/discord/ext/commands/core.py", line 94, in wrapped
    raise CommandInvokeError(exc) from exc
discord.ext.commands.errors.CommandInvokeError: Command raised an exception: Forbidden: 403 Forbidden (error code: 50013): Missing Permissions
Ignoring exception in command slap:
Traceback (most recent call last):
  File "/home/pi/Termino/termino/lib/python3.7/site-packages/discord/ext/commands/bot.py", line 939, in invoke
    await ctx.command.invoke(ctx)
  File "/home/pi/Termino/termino/lib/python3.7/site-packages/discord/ext/commands/core.py", line 855, in invoke
    await self.prepare(ctx)
  File "/home/pi/Termino/termino/lib/python3.7/site-packages/discord/ext/commands/core.py", line 789, in prepare
    await self._parse_arguments(ctx)
  File "/home/pi/Termino/termino/lib/python3.7/site-packages/discord/ext/commands/core.py", line 706, in _parse_arguments
    kwargs[name] = await self.transform(ctx, param)
  File "/home/pi/Termino/termino/lib/python3.7/site-packages/discord/ext/commands/core.py", line 542, in transform
    raise MissingRequiredArgument(param)
discord.ext.commands.errors.MissingRequiredArgument: reason is a required argument that is missing.
Ignoring exception in command slap:
Traceback (most recent call last):
  File "/home/pi/Termino/termino/lib/python3.7/site-packages/discord/ext/commands/bot.py", line 939, in invoke
    await ctx.command.invoke(ctx)
  File "/home/pi/Termino/termino/lib/python3.7/site-packages/discord/ext/commands/core.py", line 855, in invoke
    await self.prepare(ctx)
  File "/home/pi/Termino/termino/lib/python3.7/site-packages/discord/ext/commands/core.py", line 789, in prepare
    await self._parse_arguments(ctx)
  File "/home/pi/Termino/termino/lib/python3.7/site-packages/discord/ext/commands/core.py", line 706, in _parse_arguments
    kwargs[name] = await self.transform(ctx, param)
  File "/home/pi/Termino/termino/lib/python3.7/site-packages/discord/ext/commands/core.py", line 542, in transform
    raise MissingRequiredArgument(param)
discord.ext.commands.errors.MissingRequiredArgument: reason is a required argument that is missing.
Termino is ready to go.
-----------------------------------
Ignoring exception in command None:
discord.ext.commands.errors.CommandNotFound: Command "HELP" is not found
Ignoring exception in command None:
discord.ext.commands.errors.CommandNotFound: Command "hel" is not found
Ignoring exception in command slap:
Traceback (most recent call last):
  File "/home/pi/Termino/termino/lib/python3.7/site-packages/discord/ext/commands/bot.py", line 939, in invoke
    await ctx.command.invoke(ctx)
  File "/home/pi/Termino/termino/lib/python3.7/site-packages/discord/ext/commands/core.py", line 855, in invoke
    await self.prepare(ctx)
  File "/home/pi/Termino/termino/lib/python3.7/site-packages/discord/ext/commands/core.py", line 789, in prepare
    await self._parse_arguments(ctx)
  File "/home/pi/Termino/termino/lib/python3.7/site-packages/discord/ext/commands/core.py", line 697, in _parse_arguments
    transformed = await self.transform(ctx, param)
  File "/home/pi/Termino/termino/lib/python3.7/site-packages/discord/ext/commands/core.py", line 552, in transform
    return await self.do_conversion(ctx, converter, argument, param)
  File "/home/pi/Termino/termino/lib/python3.7/site-packages/discord/ext/commands/core.py", line 505, in do_conversion
    return await self._actual_conversion(ctx, converter, argument, param)
  File "/home/pi/Termino/termino/lib/python3.7/site-packages/discord/ext/commands/core.py", line 451, in _actual_conversion
    ret = await instance.convert(ctx, argument)
  File "/home/pi/Termino/termino/lib/python3.7/site-packages/discord/ext/commands/converter.py", line 195, in convert
    raise MemberNotFound(argument)
discord.ext.commands.errors.MemberNotFound: Member "<@&818352320243826690>" not found.
Termino is ready to go.
-----------------------------------
Termino is ready to go.
-----------------------------------
  File "bot.py", line 56
    await ctx.reply(embed = embd)
        ^
SyntaxError: invalid syntax
Termino is ready to go.
-----------------------------------
Ignoring exception in command kick:
Traceback (most recent call last):
  File "/home/pi/Termino/termino/lib/python3.7/site-packages/discord/ext/commands/bot.py", line 939, in invoke
    await ctx.command.invoke(ctx)
  File "/home/pi/Termino/termino/lib/python3.7/site-packages/discord/ext/commands/core.py", line 855, in invoke
    await self.prepare(ctx)
  File "/home/pi/Termino/termino/lib/python3.7/site-packages/discord/ext/commands/core.py", line 777, in prepare
    if not await self.can_run(ctx):
  File "/home/pi/Termino/termino/lib/python3.7/site-packages/discord/ext/commands/core.py", line 1087, in can_run
    return await discord.utils.async_all(predicate(ctx) for predicate in predicates)
  File "/home/pi/Termino/termino/lib/python3.7/site-packages/discord/utils.py", line 348, in async_all
    for elem in gen:
  File "/home/pi/Termino/termino/lib/python3.7/site-packages/discord/ext/commands/core.py", line 1087, in <genexpr>
    return await discord.utils.async_all(predicate(ctx) for predicate in predicates)
  File "/home/pi/Termino/termino/lib/python3.7/site-packages/discord/ext/commands/core.py", line 1790, in predicate
    raise MissingPermissions(missing)
discord.ext.commands.errors.MissingPermissions: You are missing Kick Members and Administrator permission(s) to run this command.
Ignoring exception in command kick:
Traceback (most recent call last):
  File "/home/pi/Termino/termino/lib/python3.7/site-packages/discord/ext/commands/bot.py", line 939, in invoke
    await ctx.command.invoke(ctx)
  File "/home/pi/Termino/termino/lib/python3.7/site-packages/discord/ext/commands/core.py", line 855, in invoke
    await self.prepare(ctx)
  File "/home/pi/Termino/termino/lib/python3.7/site-packages/discord/ext/commands/core.py", line 777, in prepare
    if not await self.can_run(ctx):
  File "/home/pi/Termino/termino/lib/python3.7/site-packages/discord/ext/commands/core.py", line 1087, in can_run
    return await discord.utils.async_all(predicate(ctx) for predicate in predicates)
  File "/home/pi/Termino/termino/lib/python3.7/site-packages/discord/utils.py", line 348, in async_all
    for elem in gen:
  File "/home/pi/Termino/termino/lib/python3.7/site-packages/discord/ext/commands/core.py", line 1087, in <genexpr>
    return await discord.utils.async_all(predicate(ctx) for predicate in predicates)
  File "/home/pi/Termino/termino/lib/python3.7/site-packages/discord/ext/commands/core.py", line 1790, in predicate
    raise MissingPermissions(missing)
discord.ext.commands.errors.MissingPermissions: You are missing Kick Members and Administrator permission(s) to run this command.
Termino is ready to go.
-----------------------------------
Ignoring exception in command None:
discord.ext.commands.errors.CommandNotFound: Command "really?" is not found
Ignoring exception in command None:
discord.ext.commands.errors.CommandNotFound: Command "hel" is not found
Ignoring exception in command ban:
Traceback (most recent call last):
  File "/home/pi/Termino/termino/lib/python3.7/site-packages/discord/ext/commands/core.py", line 85, in wrapped
    ret = await coro(*args, **kwargs)
  File "/home/pi/Termino/scripts/moderation/kickban.py", line 18, in ban
    await member.ban(reason = "Didn't provide a reason.")
  File "/home/pi/Termino/termino/lib/python3.7/site-packages/discord/member.py", line 541, in ban
    await self.guild.ban(self, **kwargs)
  File "/home/pi/Termino/termino/lib/python3.7/site-packages/discord/guild.py", line 2026, in ban
    await self._state.http.ban(user.id, self.id, delete_message_days, reason=reason)
  File "/home/pi/Termino/termino/lib/python3.7/site-packages/discord/http.py", line 248, in request
    raise Forbidden(r, data)
discord.errors.Forbidden: 403 Forbidden (error code: 50013): Missing Permissions

The above exception was the direct cause of the following exception:

Traceback (most recent call last):
  File "/home/pi/Termino/termino/lib/python3.7/site-packages/discord/ext/commands/bot.py", line 939, in invoke
    await ctx.command.invoke(ctx)
  File "/home/pi/Termino/termino/lib/python3.7/site-packages/discord/ext/commands/core.py", line 863, in invoke
    await injected(*ctx.args, **ctx.kwargs)
  File "/home/pi/Termino/termino/lib/python3.7/site-packages/discord/ext/commands/core.py", line 94, in wrapped
    raise CommandInvokeError(exc) from exc
discord.ext.commands.errors.CommandInvokeError: Command raised an exception: Forbidden: 403 Forbidden (error code: 50013): Missing Permissions
Termino is ready to go.
-----------------------------------
Termino is ready to go.
-----------------------------------
Ignoring exception in on_message
Traceback (most recent call last):
  File "/home/pi/Termino/termino/lib/python3.7/site-packages/discord/ext/commands/core.py", line 85, in wrapped
    ret = await coro(*args, **kwargs)
  File "/home/pi/Termino/scripts/moderation/kickban.py", line 9, in kick
    await member.kick(reason = "Didn't provide a reason.")
  File "/home/pi/Termino/termino/lib/python3.7/site-packages/discord/member.py", line 555, in kick
    await self.guild.kick(self, reason=reason)
  File "/home/pi/Termino/termino/lib/python3.7/site-packages/discord/guild.py", line 1997, in kick
    await self._state.http.kick(user.id, self.id, reason=reason)
  File "/home/pi/Termino/termino/lib/python3.7/site-packages/discord/http.py", line 248, in request
    raise Forbidden(r, data)
discord.errors.Forbidden: 403 Forbidden (error code: 50013): Missing Permissions

The above exception was the direct cause of the following exception:

Traceback (most recent call last):
  File "/home/pi/Termino/termino/lib/python3.7/site-packages/discord/ext/commands/bot.py", line 939, in invoke
    await ctx.command.invoke(ctx)
  File "/home/pi/Termino/termino/lib/python3.7/site-packages/discord/ext/commands/core.py", line 863, in invoke
    await injected(*ctx.args, **ctx.kwargs)
  File "/home/pi/Termino/termino/lib/python3.7/site-packages/discord/ext/commands/core.py", line 94, in wrapped
    raise CommandInvokeError(exc) from exc
discord.ext.commands.errors.CommandInvokeError: Command raised an exception: Forbidden: 403 Forbidden (error code: 50013): Missing Permissions

During handling of the above exception, another exception occurred:

Traceback (most recent call last):
  File "/home/pi/Termino/termino/lib/python3.7/site-packages/discord/ext/commands/core.py", line 71, in wrapped
    ret = await coro(*args, **kwargs)
  File "/home/pi/Termino/scripts/moderation/kickban.py", line 32, in ban_error
    elif isinstance(error, MissingPermissions):
NameError: name 'MissingPermissions' is not defined

The above exception was the direct cause of the following exception:

Traceback (most recent call last):
  File "/home/pi/Termino/termino/lib/python3.7/site-packages/discord/client.py", line 343, in _run_event
    await coro(*args, **kwargs)
  File "/home/pi/Termino/termino/lib/python3.7/site-packages/discord/ext/commands/bot.py", line 979, in on_message
    await self.process_commands(message)
  File "/home/pi/Termino/termino/lib/python3.7/site-packages/discord/ext/commands/bot.py", line 976, in process_commands
    await self.invoke(ctx)
  File "/home/pi/Termino/termino/lib/python3.7/site-packages/discord/ext/commands/bot.py", line 943, in invoke
    await ctx.command.dispatch_error(ctx, exc)
  File "/home/pi/Termino/termino/lib/python3.7/site-packages/discord/ext/commands/core.py", line 424, in dispatch_error
    await injected(ctx, error)
  File "/home/pi/Termino/termino/lib/python3.7/site-packages/discord/ext/commands/core.py", line 77, in wrapped
    raise CommandInvokeError(exc) from exc
discord.ext.commands.errors.CommandInvokeError: Command raised an exception: NameError: name 'MissingPermissions' is not defined
Termino is ready to go.
-----------------------------------
Ignoring exception in on_message
Traceback (most recent call last):
  File "/home/pi/Termino/termino/lib/python3.7/site-packages/discord/ext/commands/core.py", line 85, in wrapped
    ret = await coro(*args, **kwargs)
  File "/home/pi/Termino/scripts/moderation/kickban.py", line 19, in ban
    await member.ban(reason = reason)
  File "/home/pi/Termino/termino/lib/python3.7/site-packages/discord/member.py", line 541, in ban
    await self.guild.ban(self, **kwargs)
  File "/home/pi/Termino/termino/lib/python3.7/site-packages/discord/guild.py", line 2026, in ban
    await self._state.http.ban(user.id, self.id, delete_message_days, reason=reason)
  File "/home/pi/Termino/termino/lib/python3.7/site-packages/discord/http.py", line 248, in request
    raise Forbidden(r, data)
discord.errors.Forbidden: 403 Forbidden (error code: 50013): Missing Permissions

The above exception was the direct cause of the following exception:

Traceback (most recent call last):
  File "/home/pi/Termino/termino/lib/python3.7/site-packages/discord/ext/commands/bot.py", line 939, in invoke
    await ctx.command.invoke(ctx)
  File "/home/pi/Termino/termino/lib/python3.7/site-packages/discord/ext/commands/core.py", line 863, in invoke
    await injected(*ctx.args, **ctx.kwargs)
  File "/home/pi/Termino/termino/lib/python3.7/site-packages/discord/ext/commands/core.py", line 94, in wrapped
    raise CommandInvokeError(exc) from exc
discord.ext.commands.errors.CommandInvokeError: Command raised an exception: Forbidden: 403 Forbidden (error code: 50013): Missing Permissions

During handling of the above exception, another exception occurred:

Traceback (most recent call last):
  File "/home/pi/Termino/termino/lib/python3.7/site-packages/discord/ext/commands/core.py", line 71, in wrapped
    ret = await coro(*args, **kwargs)
  File "/home/pi/Termino/scripts/moderation/kickban.py", line 32, in ban_error
    elif isinstance(error, MissingPermissions):
NameError: name 'MissingPermissions' is not defined

The above exception was the direct cause of the following exception:

Traceback (most recent call last):
  File "/home/pi/Termino/termino/lib/python3.7/site-packages/discord/client.py", line 343, in _run_event
    await coro(*args, **kwargs)
  File "/home/pi/Termino/termino/lib/python3.7/site-packages/discord/ext/commands/bot.py", line 979, in on_message
    await self.process_commands(message)
  File "/home/pi/Termino/termino/lib/python3.7/site-packages/discord/ext/commands/bot.py", line 976, in process_commands
    await self.invoke(ctx)
  File "/home/pi/Termino/termino/lib/python3.7/site-packages/discord/ext/commands/bot.py", line 943, in invoke
    await ctx.command.dispatch_error(ctx, exc)
  File "/home/pi/Termino/termino/lib/python3.7/site-packages/discord/ext/commands/core.py", line 424, in dispatch_error
    await injected(ctx, error)
  File "/home/pi/Termino/termino/lib/python3.7/site-packages/discord/ext/commands/core.py", line 77, in wrapped
    raise CommandInvokeError(exc) from exc
discord.ext.commands.errors.CommandInvokeError: Command raised an exception: NameError: name 'MissingPermissions' is not defined
SSL error in data received
protocol: <asyncio.sslproto.SSLProtocol object at 0xb4658dd0>
transport: <_SelectorSocketTransport fd=7 read=polling write=<idle, bufsize=0>>
Traceback (most recent call last):
  File "/usr/lib/python3.7/asyncio/sslproto.py", line 526, in data_received
    ssldata, appdata = self._sslpipe.feed_ssldata(data)
  File "/usr/lib/python3.7/asyncio/sslproto.py", line 207, in feed_ssldata
    self._sslobj.unwrap()
  File "/usr/lib/python3.7/ssl.py", line 767, in unwrap
    return self._sslobj.shutdown()
ssl.SSLError: [SSL: KRB5_S_INIT] application data after close notify (_ssl.c:2609)
Ignoring exception in on_message
Traceback (most recent call last):
  File "/home/pi/Termino/termino/lib/python3.7/site-packages/discord/ext/commands/bot.py", line 939, in invoke
    await ctx.command.invoke(ctx)
  File "/home/pi/Termino/termino/lib/python3.7/site-packages/discord/ext/commands/core.py", line 855, in invoke
    await self.prepare(ctx)
  File "/home/pi/Termino/termino/lib/python3.7/site-packages/discord/ext/commands/core.py", line 789, in prepare
    await self._parse_arguments(ctx)
  File "/home/pi/Termino/termino/lib/python3.7/site-packages/discord/ext/commands/core.py", line 697, in _parse_arguments
    transformed = await self.transform(ctx, param)
  File "/home/pi/Termino/termino/lib/python3.7/site-packages/discord/ext/commands/core.py", line 542, in transform
    raise MissingRequiredArgument(param)
discord.ext.commands.errors.MissingRequiredArgument: member is a required argument that is missing.

During handling of the above exception, another exception occurred:

Traceback (most recent call last):
  File "/home/pi/Termino/termino/lib/python3.7/site-packages/discord/ext/commands/core.py", line 71, in wrapped
    ret = await coro(*args, **kwargs)
  File "/home/pi/Termino/scripts/moderation/kickban.py", line 25, in kick_error
    elif isinstance(error, MissingPermissions):
NameError: name 'MissingPermissions' is not defined

The above exception was the direct cause of the following exception:

Traceback (most recent call last):
  File "/home/pi/Termino/termino/lib/python3.7/site-packages/discord/client.py", line 343, in _run_event
    await coro(*args, **kwargs)
  File "/home/pi/Termino/termino/lib/python3.7/site-packages/discord/ext/commands/bot.py", line 979, in on_message
    await self.process_commands(message)
  File "/home/pi/Termino/termino/lib/python3.7/site-packages/discord/ext/commands/bot.py", line 976, in process_commands
    await self.invoke(ctx)
  File "/home/pi/Termino/termino/lib/python3.7/site-packages/discord/ext/commands/bot.py", line 943, in invoke
    await ctx.command.dispatch_error(ctx, exc)
  File "/home/pi/Termino/termino/lib/python3.7/site-packages/discord/ext/commands/core.py", line 424, in dispatch_error
    await injected(ctx, error)
  File "/home/pi/Termino/termino/lib/python3.7/site-packages/discord/ext/commands/core.py", line 77, in wrapped
    raise CommandInvokeError(exc) from exc
discord.ext.commands.errors.CommandInvokeError: Command raised an exception: NameError: name 'MissingPermissions' is not defined
Termino is ready to go.
-----------------------------------
Traceback (most recent call last):
  File "bot.py", line 2, in <module>
    import discord
ModuleNotFoundError: No module named 'discord'
Termino is ready to go.
-----------------------------------
Termino is ready to go.
-----------------------------------
Termino is ready to go.
-----------------------------------
Termino is ready to go.
-----------------------------------
  File "bot.py", line 17
    print(f'{termino.user.name} is ready to go.')
        ^
SyntaxError: invalid syntax
Termino is ready to go.
-----------------------------------
Command raised an exception: Forbidden: 403 Forbidden (error code: 50013): Missing Permissions
Termino is ready to go.
-----------------------------------
Termino is ready to go.
-----------------------------------
Termino is ready to go.
-----------------------------------
Command raised an exception: Forbidden: 403 Forbidden (error code: 50013): Missing Permissions
reason is a required argument that is missing.
Termino is ready to go.
-----------------------------------
Termino is ready to go.
-----------------------------------
Termino is ready to go.
-----------------------------------
Termino is ready to go.
-----------------------------------
